Workbook

Sheet Sheet1
B2: Participant | C2: Sex | D2: Age | E2: Height | F2: Mass | G2: RunningDaysAWeek | H2: KmAWeek | I2: Injuries12Months | J2: Time10K | K2: LT | L2: VO2max | M2: RQ | N2: HRmax | O2: RPEmax | P2: MaxCompletedSpeed | Q2: MaxStartedSpeed | R2: Temperature | S2: Humidity | T2: Pressure | U2: EE10 | V2: EE11 | W2: EE12 | X2: EE13 | Y2: EE14 | Z2: EE15 | AA2: EE16 | AB2: EE17 | AC2: EE18 | AD2: EE19 | AE2: EE20 | AF2: VO10 | AG2: VO11 | AH2: VO12 | AI2: VO13 | AJ2: VO14 | AK2: VO15 | AL2: VO16 | AM2: VO17 | AN2: VO18 | AO2: VO19 | AP2: VO20 | AQ2: HR10 | AR2: HR11 | AS2: HR12 | AT2: HR13 | AU2: HR14 | AV2: HR15 | AW2: HR16 | AX2: HR17 | AY2: HR18 | AZ2: HR19 | BA2: HR20 | BB2: PelvWidth | BC2: ThiLgth_r | BD2: ThiLgth_l | BE2: ShaLgth_r | BF2: ShaLgth_l | BG2: LegLgth_r | BH2: LegLgth_l | BI2: FootLgth_r | BJ2: FootLgth_l | BK2: TrunkLgth | BL2: Sess2_time | BM2: Sess2_RPE | BN2: Sess2_La | BO2: EEJW10 | BP2: EEJW11 | BQ2: EEJW12 | BR2: EEJW13 | BS2: EEJW14 | BT2: EEJW15 | BU2: EEJW16 | BV2: EEJW17 | BW2: EEJW18 | BX2: EEJW19 | BY2: EEJW20 | BZ2: RPE10 | CA2: RPE11 | CB2: RPE12 | CC2: RPE13 | CD2: RPE14 | CE2: RPE15 | CF2: RPE16 | CG2: RPE17 | CH2: RPE18 | CI2: RPE19 | CJ2: RPE20 | CK2: RPE21 | CL2: RPE22 | CM2: RPE23 | CN2: RPE24 | CO2: RPE25
B3: P001 | C3: Male | D3: 41 | E3: 1.84 | F3: 83.9 | G3: 5 | H3: 48 | I3: No | J3: 0.032222222 | K3: 12.53948 | L3: 47.362669 | M3: 1.16 | N3: 185 | O3: 19 | P3: 14 | Q3: 15 | R3: 23.618337 | S3: 58.527054 | T3: 736 | U3: 15.107333 | V3: 15.868286 | W3: 17.038919 | AF3: 3090.6978 | AG3: 3240.0346 | AH3: 3460.7451 | AQ3: 138.51515 | AR3: 149.67568 | AS3: 160.97368 | BB3: 0.15723504 | BC3: 0.45637373 | BD3: 0.46803696 | BE3: 0.4423697 | BF3: 0.43131979 | BG3: 1.0465045 | BH3: 1.0478401 | BI3: 0.28734429 | BJ3: 0.29108186 | BK3: 0.79282769 | BL3: 0.019328704 | BM3: 19 | BN3: 8.4 | BO3: 15.344628 | BP3: 16.102319 | BQ3: 17.243051 | BZ3: 9 | CA3: 11 | CB3: 12 | CC3: 14 | CD3: 16 | CE3: 19
B4: P002 | C4: Male | D4: 31 | E4: 1.79 | F4: 72.8 | G4: 2 | H4: 20 | I4: No | J4: 0.029166667 | K4: 14.511581 | L4: 61.060415 | M4: 0.84 | N4: 189 | O4: 18 | P4: 17 | Q4: 17 | R4: 23.900812 | S4: 59.448206 | T4: 756.99255 | U4: 11.355333 | V4: 13.476562 | W4: 14.921667 | X4: 16.68129 | Y4: 17.620541 | AF4: 2372.0338 | AG4: 2795.4297 | AH4: 3091.7683 | AI4: 3455.8178 | AJ4: 3668.3431 | AQ4: 113.90323 | AR4: 136.27273 | AS4: 150.9697 | AT4: 163.24242 | AU4: 171.73684 | BB4: 0.17320023 | BC4: 0.42885215 | BD4: 0.430288 | BE4: 0.41606558 | BF4: 0.42444645 | BG4: 0.99658136 | BH4: 1.0029868 | BI4: 0.28038095 | BJ4: 0.28266007 | BK4: 0.79021593 | BL4: 0.011886574 | BM4: 18 | BN4: 9.5 | BO4: 11.813627 | BP4: 13.804852 | BQ4: 15.254769 | BR4: 17.085131 | BS4: 18.057745 | CA4: 11 | CB4: 13 | CC4: 13 | CD4: 14 | CE4: 15 | CF4: 16 | CG4: 16 | CH4: 18
B5: P003 | C5: Male | D5: 27 | E5: 1.945 | F5: 75.3 | G5: 3 | H5: 20 | I5: No | J5: 0.026388889 | K5: 15.635604 | L5: 47.949441 | M5: 1.22 | N5: 199 | O5: 20 | P5: 18 | Q5: 18 | R5: 22.398243 | S5: 48.755446 | T5: 758 | U5: 11.973077 | V5: 12.33 | W5: 13.23 | X5: 13.8916 | Y5: 15.453333 | Z5: 15.585667 | AF5: 2469.7696 | AG5: 2495.442 | AH5: 2684.7433 | AI5: 2812.2398 | AJ5: 3101.2202 | AK5: 3116.8967 | AQ5: 141.48148 | AR5: 152.48 | AS5: 152.33333 | AT5: 167.07407 | AU5: 174.23077 | AV5: 180.51613 | BB5: 0.16204962 | BC5: 0.48999643 | BD5: 0.49208147 | BE5: 0.44866631 | BF5: 0.45242279 | BG5: 1.0984904 | BH5: 1.1012151 | BI5: 0.30538138 | BJ5: 0.29920829 | BK5: 0.84514722 | BL5: 0.010706019 | BM5: 20 | BN5: 8.2 | BO5: 12.212917 | BP5: 12.438839 | BQ5: 13.473661 | BR5: 13.943784 | BS5: 15.545158 | BT5: 15.650499 | BZ5: 8 | CA5: 10 | CB5: 12 | CC5: 13 | CD5: 15 | CE5: 16 | CF5: 17 | CG5: 18 | CH5: 20
B6: P004 | C6: Female | D6: 45 | E6: 1.713 | F6: 66.9 | G6: 5 | H6: 60 | I6: No | J6: 0.03125 | K6: 14.236637 | L6: 62.632095 | M6: 1.47 | N6: 169 | O6: 19 | P6: 16 | Q6: 16 | R6: 23.197408 | S6: 62.420738 | T6: 736 | U6: 11.536471 | V6: 12.297059 | W6: 13.065 | X6: 14.856087 | Y6: 16.0092 | AF6: 2358.9612 | AG6: 2490.8328 | AH6: 2668.1015 | AI6: 3024.637 | AJ6: 3236.2456 | AQ6: 120.42105 | AR6: 129.5 | AS6: 138.95455 | AT6: 149.65217 | AU6: 159.28 | BB6: 0.17299798 | BC6: 0.43072216 | BD6: 0.43263827 | BE6: 0.40784939 | BF6: 0.40577012 | BG6: 0.97989151 | BH6: 0.98300695 | BI6: 0.26685161 | BJ6: 0.26632912 | BK6: 0.73155077 | BL6: 0.010081019 | BM6: 20 | BO6: 11.658932 | BP6: 12.435519 | BQ6: 13.259318 | BR6: 15.053171 | BS6: 16.182699 | BZ6: 10 | CA6: 11 | CB6: 12 | CC6: 14 | CD6: 16 | CE6: 17 | CF6: 19 | CG6: 20
B7: P005 | C7: Female | D7: 20 | E7: 1.629 | F7: 61.8 | G7: 4 | H7: 35 | I7: No | J7: 0.031597222 | K7: 13.149565 | L7: 46.727081 | M7: 1.07 | N7: 196 | O7: 19 | P7: 15 | Q7: 15 | R7: 23.736006 | S7: 50.261006 | T7: 738.99843 | U7: 9.8658333 | V7: 10.837097 | W7: 11.86 | X7: 13.094706 | AF7: 2015.5448 | AG7: 2207.6465 | AH7: 2405.0368 | AI7: 2642.7035 | AQ7: 146.76923 | AR7: 156.84375 | AS7: 166.38235 | AT7: 178.22222 | BB7: 0.17414062 | BC7: 0.39510028 | BD7: 0.39162486 | BE7: 0.36028242 | BF7: 0.35564424 | BG7: 0.89362877 | BH7: 0.88575247 | BI7: 0.26107766 | BJ7: 0.263084 | BK7: 0.73930938 | BL7: 0.014699074 | BM7: 17 | BO7: 10.026771 | BP7: 10.98372 | BQ7: 11.99308 | BR7: 13.209979 | BZ7: 8 | CA7: 11 | CB7: 12 | CC7: 15 | CD7: 16 | CE7: 19 | CF7: 20
B8: P006 | C8: Male | D8: 27 | E8: 1.666 | F8: 61.4 | G8: 4 | H8: 30 | I8: No | J8: 0.025694444 | K8: 15.137513 | L8: 52.908876 | M8: 1.19 | N8: 179 | O8: 18 | P8: 18 | Q8: 19 | R8: 22.926381 | S8: 49.422182 | T8: 737.98859 | U8: 10.616071 | V8: 11.501875 | W8: 12.28 | X8: 12.932222 | Y8: 13.768974 | Z8: 14.172609 | AF8: 2164.8456 | AG8: 2335.3799 | AH8: 2467.4736 | AI8: 2611.228 | AJ8: 2768.0501 | AK8: 2821.8034 | AQ8: 119.26667 | AR8: 124.85294 | AS8: 133.28205 | AT8: 139.71795 | AU8: 148.19048 | AV8: 158.33333 | BB8: 0.15313812 | BC8: 0.37949546 | BD8: 0.38807014 | BE8: 0.37772465 | BF8: 0.37288995 | BG8: 0.90289123 | BH8: 0.90718969 | BI8: 0.26410117 | BJ8: 0.26397941 | BK8: 0.76095954 | BL8: 0.018506944 | BM8: 20 | BN8: 7.7 | BO8: 10.766199 | BP8: 11.638325 | BQ8: 12.360578 | BR8: 13.049374 | BS8: 13.834633 | BT8: 14.200081 | BZ8: 8 | CA8: 9 | CB8: 11 | CC8: 12 | CD8: 14 | CE8: 15 | CF8: 16 | CG8: 17 | CH8: 18 | CI8: 20
B9: P007 | C9: Male | D9: 47 | E9: 1.707 | F9: 69.4 | G9: 3 | H9: 60 | I9: No | J9: 0.03125 | K9: 14.214796 | L9: 52.291552 | M9: 1.04 | N9: 153 | O9: 19 | P9: 17 | Q9: 17 | R9: 23.452632 | S9: 47.470542 | T9: 739 | U9: 11.500741 | V9: 13.33125 | W9: 14.794375 | Y9: 16.359697 | AF9: 2338.3975 | AG9: 2663.8366 | AH9: 2974.3897 | AJ9: 3248.3186 | AQ9: 107.82143 | AR9: 116.9697 | AS9: 123.15152 | AU9: 135 | BB9: 0.1579303 | BC9: 0.42945299 | BD9: 0.43132831 | BE9: 0.40366623 | BF9: 0.40200119 | BG9: 0.97649314 | BH9: 0.97705172 | BI9: 0.28025275 | BJ9: 0.27989071 | BK9: 0.73022757 | BL9: 0.028310185 | BM9: 20 | BN9: 5.4 | BO9: 11.645634 | BP9: 13.427102 | BQ9: 14.895702 | BS9: 16.368762 | BZ9: 7 | CA9: 10 | CB9: 12 | CC9: 12 | CD9: 13 | CE9: 14 | CF9: 17 | CG9: 19 | CH9: 20
B10: P008 | C10: Female | D10: 25 | E10: 1.557 | F10: 47.3 | G10: 4 | H10: 32 | I10: No | J10: 0.029560185 | K10: 12.749899 | L10: 46.090815 | M10: 1.27 | N10: 207 | O10: 16 | P10: 14 | Q10: 15 | R10: 21.314957 | S10: 37.729769 | T10: 751 | U10: 7.2081081 | V10: 7.5412821 | W10: 8.0689583 | AF10: 1445.7942 | AG10: 1488.454 | AH10: 1582.2602 | AQ10: 156.84211 | AR10: 176.41463 | AS10: 188.9 | BB10: 0.14458816 | BC10: 0.39022682 | BD10: 0.38781552 | BE10: 0.36873628 | BF10: 0.36338126 | BG10: 0.89412255 | BH10: 0.89107072 | BI10: 0.24762747 | BJ10: 0.24799221 | BK10: 0.66440336 | BO10: 7.2429328 | BP10: 7.4981424 | BQ10: 8.0177341 | BZ10: 6 | CA10: 7 | CB10: 9 | CC10: 12 | CD10: 16 | CE10: 19
B11: P009 | C11: Male | D11: 49 | E11: 1.724 | F11: 63.3 | G11: 5 | H11: 75 | I11: No | J11: 0.027777778 | K11: 14.557281 | L11: 51.412404 | M11: 1.04 | N11: 177 | O11: 19 | P11: 17 | Q11: 18 | R11: 22.648151 | S11: 41.580137 | T11: 746.33767 | U11: 10.5496 | V11: 11.806818 | W11: 12.1108 | X11: 12.627879 | Y11: 13.807297 | AF11: 2149.9468 | AG11: 2421.0307 | AH11: 2459.5709 | AI11: 2564.6288 | AJ11: 2786.2699 | AQ11: 118.73077 | AR11: 126.16667 | AS11: 135.64286 | AT11: 142.71429 | AU11: 156 | BB11: 0.17455749 | BC11: 0.4268891 | BD11: 0.43499756 | BE11: 0.39465403 | BF11: 0.39538961 | BG11: 0.96081476 | BH11: 0.97163914 | BI11: 0.26955939 | BJ11: 0.26777471 | BK11: 0.75777305 | BL11: 0.016064815 | BM11: 20 | BN11: 10 | BO11: 10.654892 | BP11: 12.006566 | BQ11: 12.200142 | BR11: 12.779299 | BS11: 13.951477 | BZ11: 12 | CA11: 13 | CB11: 14 | CC11: 15 | CD11: 16 | CE11: 17 | CF11: 18 | CG11: 19 | CH11: 20
B12: P010 | C12: Male | D12: 27 | E12: 1.7 | F12: 76.8 | G12: 3 | H12: 15 | I12: No | J12: 0.029861111 | K12: 13.112863 | L12: 49.391254 | M12: 1.19 | N12: 193 | O12: 19 | P12: 15 | Q12: 15 | R12: 22.429656 | S12: 41.761302 | T12: 739 | U12: 13.083913 | V12: 14.385909 | W12: 15.8525 | X12: 16.502903 | AF12: 2638.8468 | AG12: 2880.6399 | AH12: 3122.2702 | AI12: 3258.5162 | AQ12: 127.76 | AR12: 146.125 | AS12: 159.7931 | AT12: 172.53125 | BB12: 0.17341847 | BC12: 0.41099359 | BD12: 0.41225068 | BE12: 0.3867722 | BF12: 0.38451684 | BG12: 0.95328096 | BH12: 0.95415381 | BI12: 0.27673085 | BJ12: 0.27596848 | BK12: 0.74628261 | BL12: 0.015659722 | BM12: 20 | BO12: 13.126815 | BP12: 14.477139 | BQ12: 15.760202 | BR12: 16.467473 | BZ12: 10 | CA12: 12 | CB12: 15 | CC12: 16 | CD12: 18 | CE12: 19 | CF12: 20
B13: P011 | C13: Male | D13: 48 | E13: 1.833 | F13: 80.7 | G13: 2 | H13: 15 | I13: No | J13: 0.029166667 | K13: 12.998403 | L13: 45.780981 | M13: 1.48 | N13: 190 | O13: 20 | P13: 15 | Q13: 16 | R13: 22.782536 | S13: 39.310207 | T13: 739 | U13: 13.9 | V13: 14.9888 | AF13: 2781.7776 | AG13: 2990.922 | AQ13: 139.17391 | AR13: 152.03846 | BB13: 0.18050829 | BC13: 0.46181702 | BD13: 0.46475609 | BE13: 0.44230054 | BF13: 0.4379255 | BG13: 1.0641392 | BH13: 1.0632874 | BI13: 0.30804186 | BJ13: 0.29916406 | BK13: 0.76928671 | BL13: 0.011446759 | BM13: 20 | BN13: 9.1 | BO13: 13.924649 | BP13: 15.458285 | BZ13: 8 | CA13: 10 | CB13: 13 | CC13: 15 | CD13: 17 | CE13: 19 | CF13: 20
B14: P012 | C14: Male | D14: 46 | E14: 1.659 | F14: 62.4 | G14: 5 | H14: 45 | I14: No | J14: 0.027662037 | K14: 14.291701 | L14: 51.706356 | M14: 1.1 | N14: 158 | O14: 19 | P14: 16 | Q14: 16 | R14: 23.290348 | S14: 40.524673 | T14: 739.99202 | U14: 10.562143 | V14: 11.514286 | W14: 12.290968 | X14: 13.187857 | Y14: 14.254286 | AF14: 2152.2275 | AG14: 2317.1963 | AH14: 2456.8989 | AI14: 2641.6773 | AJ14: 2828.9385 | AQ14: 114.62069 | AR14: 161.03333 | AS14: 128.58824 | AT14: 136.93333 | AU14: 144.36111 | BB14: 0.1566453 | BC14: 0.40674164 | BD14: 0.41060979 | BE14: 0.37605917 | BF14: 0.37415724 | BG14: 0.92748284 | BH14: 0.93290567 | BI14: 0.27716717 | BJ14: 0.27683665 | BK14: 0.72880574 | BL14: 0.013368056 | BM14: 20 | BO14: 10.677274 | BP14: 11.609422 | BQ14: 12.317752 | BR14: 13.264719 | BS14: 14.238287 | BZ14: 8 | CA14: 11 | CB14: 12 | CC14: 13 | CD14: 15 | CE14: 17 | CF14: 19 | CG14: 20
B15: P013 | C15: Male | D15: 41 | E15: 1.78 | F15: 77.8 | G15: 4 | H15: 45 | I15: No | J15: 0.027569444 | K15: 14.026649 | L15: 46.875756 | M15: 1.13 | N15: 179 | O15: 19 | P15: 16 | Q15: 17 | R15: 23.252102 | S15: 36.62728 | T15: 738 | U15: 12.051905 | V15: 13.223333 | W15: 14.685 | X15: 15.664643 | Y15: 17.092353 | AF15: 2427.7223 | AG15: 2644.8696 | AH15: 2957.1259 | AI15: 3136.246 | AJ15: 3404.0168 | AQ15: 124.47619 | AR15: 135.75 | AS15: 142.96154 | AT15: 152.23333 | AU15: 162.86111 | BB15: 0.16710982 | BC15: 0.42656244 | BD15: 0.43246727 | BE15: 0.42642434 | BF15: 0.41894671 | BG15: 1.0034385 | BH15: 1.0004411 | BI15: 0.28702453 | BJ15: 0.29053558 | BK15: 0.77806021 | BL15: 0.013171296 | BM15: 20 | BO15: 12.14653 | BP15: 13.262037 | BQ15: 14.797516 | BR15: 15.741186 | BS15: 17.127786 | BZ15: 11 | CA15: 12 | CB15: 13 | CC15: 15 | CD15: 16 | CE15: 17 | CF15: 19 | CG15: 20
B16: P014 | C16: Female | D16: 34 | E16: 1.565 | F16: 50.9 | G16: 6 | H16: 90 | I16: No | J16: 0.026168981 | K16: 14.129391 | L16: 54.276197 | M16: 1.16 | N16: 186 | O16: 20 | P16: 16 | Q16: 17 | R16: 23.498567 | S16: 35.386348 | T16: 745 | U16: 9.5784615 | V16: 10.300345 | W16: 11.076667 | X16: 11.994706 | Y16: 12.399412 | AF16: 2001.7601 | AG16: 2149.3995 | AH16: 2300.637 | AI16: 2461.0652 | AJ16: 2535.5057 | AQ16: 121.40741 | AR16: 133.13333 | AS16: 142.83871 | AT16: 155.80556 | AU16: 165.59459 | BB16: 0.14629385 | BC16: 0.38660721 | BD16: 0.37583016 | BE16: 0.35289288 | BF16: 0.35262936 | BG16: 0.82415344 | BH16: 0.81848787 | BI16: 0.24787166 | BJ16: 0.25063912 | BK16: 0.74367935 | BO16: 9.7407743 | BP16: 10.598448 | BQ16: 11.319917 | BR16: 12.222794 | BS16: 12.592065 | BZ16: 9 | CA16: 11 | CB16: 12 | CC16: 13 | CD16: 15 | CE16: 17 | CF16: 18 | CG16: 20
B17: P015 | C17: Female | D17: 45 | E17: 1.644 | F17: 59.2 | G17: 6 | H17: 80 | I17: No | J17: 0.028287037 | K17: 13.412252 | L17: 47.025349 | M17: 1.36 | N17: 166 | O17: 19 | P17: 16 | Q17: 16 | R17: 23.359529 | S17: 36.91684 | T17: 743.4255 | U17: 9.9122222 | V17: 10.467241 | W17: 11.42871 | X17: 12.556286 | AF17: 2020.2249 | AG17: 2128.5202 | AH17: 2276.9208 | AI17: 2504.5024 | AQ17: 120.06897 | AR17: 129.36667 | AS17: 140.21875 | AT17: 148.92105 | BB17: 0.16849219 | BC17: 0.41613553 | BD17: 0.41614978 | BE17: 0.38601112 | BF17: 0.39314571 | BG17: 0.89530055 | BH17: 0.90130739 | BI17: 0.25691399 | BJ17: 0.2584768 | BK17: 0.74569603 | BM17: 19 | BN17: 3.9 | BO17: 10.076469 | BP17: 10.605388 | BQ17: 11.452564 | BR17: 12.59437 | BZ17: 9 | CA17: 10 | CB17: 11 | CC17: 12 | CD17: 14 | CE17: 17 | CF17: 19
B18: P016 | C18: Male | D18: 29 | E18: 1.891 | F18: 83.6 | G18: 3 | H18: 37 | I18: No | J18: 0.027777778 | K18: 14.272784 | L18: 66.068475 | M18: 0.66 | N18: 189 | O18: 20 | P18: 17 | Q18: 18 | R18: 22.498318 | S18: 37.917903 | T18: 739 | U18: 15.1105 | V18: 16.8785 | W18: 19.296538 | X18: 20.24 | Y18: 22.749744 | AF18: 3221.0362 | AG18: 3566.4402 | AH18: 4080.341 | AI18: 4265.9972 | AJ18: 4867.8884 | AQ18: 152.2 | AR18: 161.8 | AS18: 169.46154 | AT18: 175.40741 | AU18: 181.4878 | BB18: 0.19300653 | BC18: 0.46107418 | BD18: 0.46465459 | BE18: 0.43429984 | BF18: 0.44343418 | BG18: 0.99659566 | BH18: 1.0057065 | BI18: 0.30278727 | BJ18: 0.30092825 | BK18: 0.88984893 | BM18: 20 | BO18: 15.779292 | BP18: 17.430394 | BQ18: 19.928448 | BR18: 20.769285 | BS18: 23.646864 | BZ18: 7 | CA18: 9 | CB18: 10 | CC18: 13 | CD18: 14 | CE18: 16 | CF18: 18 | CG18: 19 | CH18: 20
B19: P017 | C19: Male | D19: 22 | E19: 1.773 | F19: 59.3 | G19: 5 | H19: 58 | I19: Knee pain | J19: 0.025 | K19: 15.002059 | L19: 56.684908 | M19: 1.15 | N19: 191 | O19: 20 | P19: 18 | Q19: 19 | R19: 23.33274 | S19: 36.884768 | T19: 742.18299 | U19: 11.11129 | V19: 11.160303 | W19: 12.406286 | X19: 12.768 | Y19: 13.165676 | Z19: 14.363784 | AF19: 2267.4388 | AG19: 2256.6213 | AH19: 2483.6665 | AI19: 2561.6559 | AJ19: 2630.2057 | AK19: 2867.4454 | AQ19: 127.84848 | AR19: 142.68571 | AS19: 150.91667 | AT19: 158 | AU19: 165.73684 | AV19: 172.46154 | BB19: 0.15349964 | BC19: 0.45512551 | BD19: 0.45489969 | BE19: 0.42650539 | BF19: 0.42484889 | BG19: 0.97609675 | BH19: 0.97973101 | BI19: 0.28320564 | BJ19: 0.28256997 | BK19: 0.79508612 | BL19: 0.023831019 | BM19: 20 | BO19: 11.272205 | BP19: 11.247793 | BQ19: 12.45559 | BR19: 12.823623 | BS19: 13.213664 | BT19: 14.410561 | BZ19: 9 | CA19: 11 | CB19: 12 | CC19: 13 | CD19: 14 | CE19: 15 | CF19: 16 | CG19: 17 | CH19: 18 | CI19: 20
B20: P018 | C20: Male | D20: 46 | E20: 1.799 | F20: 75.3 | G20: 3 | H20: 30 | I20: No | J20: 0.025046296 | K20: 15.139812 | L20: 53.842701 | M20: 1.27 | N20: 169 | O20: 20 | P20: 18 | Q20: 19 | R20: 20.113725 | S20: 34.922323 | T20: 754.00075 | U20: 12.762353 | V20: 13.137778 | W20: 14.773333 | X20: 15.54 | Y20: 16.682692 | Z20: 18.112692 | AF20: 2610.9248 | AG20: 2654.7956 | AH20: 2964.0823 | AI20: 3121.8063 | AJ20: 3329.0102 | AK20: 3567.6404 | AQ20: 104.72222 | AR20: 114.4 | AS20: 121.54545 | AT20: 131.04348 | AU20: 139.55556 | AV20: 147.44444 | BB20: 0.18124487 | BC20: 0.42430346 | BD20: 0.43852056 | BE20: 0.42003005 | BF20: 0.41153197 | BG20: 0.93966342 | BH20: 0.94865033 | BI20: 0.28250483 | BJ20: 0.27706343 | BK20: 0.85484313 | BM20: 20 | BN20: 6 | BO20: 12.931143 | BP20: 13.288691 | BQ20: 14.8099 | BR20: 15.591422 | BS20: 16.698796 | BT20: 18.132339 | BZ20: 7 | CA20: 9 | CB20: 10 | CC20: 11 | CD20: 12 | CE20: 13 | CF20: 15 | CG20: 16 | CH20: 19 | CI20: 20
B21: P019 | C21: Male | D21: 50 | E21: 1.797 | F21: 75.6 | G21: 5 | H21: 45 | I21: No | J21: 0.026388889 | K21: 14.93478 | L21: 46.834105 | M21: 1.31 | N21: 173 | O21: 20 | P21: 17 | Q21: 18 | R21: 19.779779 | S21: 36.074772 | T21: 750 | U21: 10.476087 | V21: 11.362609 | W21: 12.861923 | X21: 13.798462 | Y21: 15.056452 | AF21: 2109.8083 | AG21: 2299.136 | AH21: 2590.3661 | AI21: 2768.6987 | AJ21: 2999.8679 | AQ21: 98.88 | AR21: 110.08333 | AS21: 122.74074 | AT21: 133.85714 | AU21: 144.96875 | BB21: 0.17405633 | BC21: 0.44579 | BD21: 0.44772826 | BE21: 0.42668624 | BF21: 0.42139608 | BG21: 0.96538401 | BH21: 0.96786367 | BI21: 0.28334852 | BJ21: 0.28368662 | BK21: 0.83037616 | BL21: 0.017071759 | BM21: 20 | BN21: 7.7 | BO21: 10.603739 | BP21: 11.481946 | BQ21: 13.084188 | BR21: 13.893604 | BS21: 15.071402 | BZ21: 11 | CA21: 12 | CB21: 12 | CC21: 13 | CD21: 14 | CE21: 15 | CF21: 17 | CG21: 19 | CH21: 20
B22: P020 | C22: Male | D22: 41 | E22: 1.841 | F22: 77.1 | G22: 3 | H22: 60 | I22: No | J22: 0.024930556 | K22: 14.877686 | L22: 49.287316 | M22: 1.3 | N22: 186 | O22: 19 | P22: 17 | Q22: 18 | R22: 23.498554 | S22: 43.096891 | T22: 730 | U22: 11.914615 | V22: 12.746296 | W22: 13.98129 | X22: 14.255455 | Y22: 15.2 | AF22: 2386.7945 | AG22: 2522.5246 | AH22: 2780.2939 | AI22: 2821.1808 | AJ22: 3003.3956 | AQ22: 125.19231 | AR22: 136.62069 | AS22: 143.5 | AT22: 150.85714 | AU22: 160.14286 | BB22: 0.17389872 | BC22: 0.45057313 | BD22: 0.46074489 | BE22: 0.42748162 | BF22: 0.43330513 | BG22: 0.97201063 | BH22: 0.98209875 | BI22: 0.29726646 | BJ22: 0.2974532 | BK22: 0.86394531 | BM22: 14 | BO22: 11.988842 | BP22: 12.751216 | BQ22: 14.051174 | BR22: 14.217664 | BS22: 15.164899 | BZ22: 7 | CA22: 7 | CB22: 8 | CC22: 9 | CD22: 11 | CE22: 12 | CF22: 14 | CG22: 15 | CH22: 19
B23: P021 | C23: Male | D23: 31 | E23: 1.848 | F23: 82.3 | G23: 4 | H23: 55 | I23: No | J23: 0.030243056 | K23: 13.230504 | L23: 45.96564 | M23: 1.28 | N23: 188 | O23: 20 | P23: 15 | Q23: 16 | R23: 22.132422 | S23: 39.301602 | T23: 739 | U23: 13.996667 | V23: 14.476522 | W23: 14.9412 | X23: 16.736538 | AF23: 2819.8218 | AG23: 2907.2655 | AH23: 2982.3776 | AI23: 3315.1202 | AQ23: 134.57895 | AR23: 147.84 | AS23: 155.53846 | AT23: 164.03704 | BB23: 0.17455823 | BC23: 0.45306269 | BD23: 0.44808337 | BE23: 0.43680073 | BF23: 0.44427083 | BG23: 0.98955654 | BH23: 0.99073122 | BI23: 0.29843801 | BJ23: 0.29634205 | BK23: 0.85785612 | BM23: 20 | BN23: 6.6 | BO23: 14.112132 | BP23: 14.568068 | BQ23: 14.989344 | BR23: 16.68439 | BZ23: 9 | CA23: 11 | CB23: 13 | CC23: 15 | CD23: 17 | CE23: 18 | CF23: 20
B24: P022 | C24: Male | D24: 43 | E24: 1.737 | F24: 65.7 | G24: 5 | H24: 60 | I24: No | J24: 0.024189815 | K24: 15.275271 | L24: 56.331233 | M24: 1.15 | N24: 189 | O24: 20 | P24: 17 | Q24: 18 | R24: 21.171901 | S24: 31.734035 | T24: 731 | U24: 10.610435 | V24: 11.802381 | W24: 12.412593 | X24: 13.947143 | Y24: 14.945172 | Z24: 16.224643 | AF24: 2186.0405 | AG24: 2370.4337 | AH24: 2526.8315 | AI24: 2832.7908 | AJ24: 3023.8655 | AK24: 3263.1049 | AQ24: 116.95652 | AR24: 123.6087 | AS24: 134.44828 | AT24: 142.54839 | AU24: 154.3871 | AV24: 165.06667 | BB24: 0.15705935 | BC24: 0.43419829 | BD24: 0.43042792 | BE24: 0.401558 | BF24: 0.40993333 | BG24: 0.92374099 | BH24: 0.92609577 | BI24: 0.28370536 | BJ24: 0.2846059 | BK24: 0.81208162 | BL24: 0.014803241 | BM24: 19 | BN24: 6.2 | BO24: 10.934364 | BP24: 11.94482 | BQ24: 12.706071 | BR24: 14.112117 | BS24: 15.037535 | BT24: 16.3662 | BZ24: 10 | CA24: 12 | CB24: 13 | CC24: 15 | CD24: 16 | CE24: 17 | CF24: 18 | CG24: 19 | CH24: 20
B25: P023 | C25: Female | D25: 49 | E25: 1.634 | F25: 60.3 | G25: 4 | H25: 52 | I25: No | J25: 0.030138889 | K25: 13.554094 | L25: 48.216458 | M25: 1.13 | N25: 159 | O25: 19 | P25: 15 | Q25: 15 | R25: 20.614709 | S25: 32.779833 | T25: 735 | V25: 11.184 | W25: 11.693611 | X25: 12.833514 | AG25: 2236.3736 | AH25: 2326.7765 | AI25: 2532.5285 | AR25: 121.66667 | AS25: 131.10811 | AT25: 143.23684 | BB25: 0.17564821 | BC25: 0.38644544 | BD25: 0.39518133 | BE25: 0.36797577 | BF25: 0.37132388 | BG25: 0.86152519 | BH25: 0.87200497 | BI25: 0.25866958 | BJ25: 0.2560418 | BK25: 0.76723492 | BM25: 18 | BP25: 11.230201 | BQ25: 11.726408 | BR25: 12.776666 | BZ25: 8 | CA25: 9 | CB25: 11 | CC25: 12 | CD25: 15 | CE25: 19
B26: P024 | C26: Male | D26: 22 | E26: 1.79 | F26: 69 | G26: 4 | H26: 8 | I26: No | J26: 0.025694444 | K26: 15.018323 | L26: 52.774203 | M26: 1.27 | N26: 206 | O26: 20 | P26: 18 | Q26: 18 | R26: 23.909689 | S26: 31.283243 | T26: 730.79931 | U26: 12.133333 | V26: 12.137273 | W26: 13.829062 | X26: 14.532857 | Y26: 15.367273 | Z26: 16.520455 | AF26: 2497.2024 | AG26: 2480.9417 | AH26: 2775.0389 | AI26: 2919.6664 | AJ26: 3066.9692 | AK26: 3273.0176 | AQ26: 139.24138 | AR26: 150.47826 | AS26: 159.9697 | AT26: 167.32432 | AU26: 176.57143 | AV26: 183.54348 | BB26: 0.17092654 | BC26: 0.4478591 | BD26: 0.44853847 | BE26: 0.40820764 | BF26: 0.40716019 | BG26: 0.95812952 | BH26: 0.95995654 | BI26: 0.28025069 | BJ26: 0.27720973 | BK26: 0.83095697 | BL26: 0.016921296 | BM26: 19 | BN26: 6.5 | BO26: 12.532412 | BP26: 12.357829 | BQ26: 13.910455 | BR26: 14.626558 | BS26: 15.415674 | BT26: 16.511186 | BZ26: 10 | CA26: 11 | CB26: 12 | CC26: 13 | CD26: 14 | CE26: 15 | CF26: 15 | CG26: 17 | CH26: 20
B27: P025 | C27: Female | D27: 45 | E27: 1.667 | F27: 58 | G27: 7 | H27: 55 | I27: No | J27: 0.030081019 | K27: 13.052477 | L27: 51.984415 | M27: 0.73 | N27: 164 | O27: 20 | P27: 15 | Q27: 16 | R27: 21.158865 | S27: 29.608865 | T27: 731.76439 | U27: 10.333125 | V27: 11.511351 | W27: 11.583256 | X27: 12.193488 | AF27: 2145.6474 | AG27: 2408.9375 | AH27: 2425.2086 | AI27: 2540.0113 | AQ27: 130.93939 | AR27: 141.05263 | AS27: 145.48889 | AT27: 150.78261 | BB27: 0.18581018 | BC27: 0.40171141 | BD27: 0.39710903 | BE27: 0.37681636 | BF27: 0.36922067 | BG27: 0.86977189 | BH27: 0.86488376 | BI27: 0.26392861 | BJ27: 0.26396981 | BK27: 0.79967217 | BL27: 0.014537037 | BM27: 20 | BN27: 5.7 | BO27: 10.586661 | BP27: 11.854061 | BQ27: 11.890994 | BR27: 12.496479 | BZ27: 11 | CA27: 12 | CB27: 13 | CC27: 14 | CD27: 17 | CE27: 19 | CF27: 20
B28: P026 | C28: Male | D28: 46 | E28: 1.785 | F28: 76 | G28: 5 | H28: 35 | I28: No | J28: 0.028819444 | K28: 13.38001 | L28: 41.619177 | M28: 1.19 | N28: 173 | O28: 19 | P28: 16 | Q28: 17 | R28: 20.978814 | S28: 32.194915 | T28: 739.94237 | U28: 12.780952 | V28: 13.843333 | W28: 14.69 | X28: 15.041852 | AF28: 2565.0867 | AG28: 2755.8711 | AH28: 2899.886 | AI28: 2965.8363 | AQ28: 126.45455 | AR28: 137.96154 | AS28: 146.53846 | AT28: 153.86667 | BB28: 0.1513152 | BC28: 0.49121156 | BD28: 0.48503186 | BE28: 0.42911304 | BF28: 0.42941371 | BG28: 1.0125474 | BH28: 1.0084919 | BI28: 0.27447043 | BJ28: 0.27834939 | BK28: 0.77448035 | BL28: 0.01525463 | BM28: 19 | BN28: 10.2 | BO28: 12.818553 | BP28: 13.869155 | BQ28: 14.655309 | BR28: 14.997699 | BZ28: 7 | CA28: 8 | CB28: 8 | CC28: 10 | CD28: 11 | CE28: 14 | CF28: 17 | CG28: 19
B29: P027 | C29: Male | D29: 44 | E29: 1.818 | F29: 64.4 | G29: 6 | H29: 84 | I29: Sprained ankle 6 months ago for a week and knee pain two weeks 10 months ago | J29: 0.025173611 | K29: 15.417754 | L29: 49.275352 | M29: 1.21 | N29: 172 | O29: 20 | P29: 17 | Q29: 18 | R29: 19.627323 | S29: 30.267722 | T29: 735 | U29: 10.781364 | V29: 11.148261 | W29: 12.059167 | X29: 12.684333 | Y29: 13.536552 | Z29: 13.942121 | AF29: 2177.2847 | AG29: 2241.5001 | AH29: 2416.4616 | AI29: 2530.483 | AJ29: 2696.3946 | AK29: 2742.632 | AQ29: 106.86957 | AR29: 111.24 | AS29: 123.53846 | AT29: 132.70968 | AU29: 140.1875 | AV29: 151.62857 | BB29: 0.15793415 | BC29: 0.46035525 | BD29: 0.47173296 | BE29: 0.44284496 | BF29: 0.43477554 | BG29: 0.99625184 | BH29: 1.0094201 | BI29: 0.29040104 | BJ29: 0.28556521 | BK29: 0.81516402 | BM29: 18 | BN29: 4.1 | BO29: 11.021387 | BP29: 11.229173 | BQ29: 12.13751 | BR29: 12.743739 | BS29: 13.555458 | BT29: 13.899727 | BZ29: 7 | CA29: 9 | CB29: 10 | CC29: 11 | CD29: 11 | CE29: 13 | CF29: 15 | CG29: 17 | CH29: 20
B30: P028 | C30: Male | D30: 46 | E30: 1.778 | F30: 68.6 | G30: 4 | H30: 50 | I30: No | J30: 0.025694444 | K30: 14.137932 | L30: 52.14699 | M30: 1.2 | N30: 177 | O30: 20 | P30: 16 | Q30: 17 | R30: 19.94968 | S30: 30.9768 | T30: 733.8944 | U30: 10.929091 | V30: 12.298462 | W30: 13.923214 | X30: 14.840606 | Y30: 15.878 | AF30: 2248.5779 | AG30: 2490.5325 | AH30: 2795.0077 | AI30: 2953.1731 | AJ30: 3144.0911 | AQ30: 115.78261 | AR30: 126.18519 | AS30: 138.58621 | AT30: 148.20588 | AU30: 157.7027 | BB30: 0.17359337 | BC30: 0.46373214 | BD30: 0.45661608 | BE30: 0.41965347 | BF30: 0.41561968 | BG30: 0.97504099 | BH30: 0.96907288 | BI30: 0.28126008 | BJ30: 0.28129434 | BK30: 0.80594306 | BM30: 19 | BO30: 11.133498 | BP30: 12.432183 | BQ30: 14.007791 | BR30: 14.865337 | BS30: 15.869688 | BZ30: 7 | CA30: 9 | CB30: 11 | CC30: 12 | CD30: 14 | CE30: 17 | CF30: 19 | CG30: 20
B31: P029 | C31: Male | D31: 44 | E31: 1.755 | F31: 76.7 | G31: 4 | H31: 40 | I31: No | J31: 0.030555556 | K31: 12.69827 | L31: 54.741303 | M31: 0.65 | N31: 177 | O31: 20 | P31: 14 | Q31: 15 | R31: 23.070878 | S31: 39.095878 | T31: 728.99552 | U31: 12.938065 | V31: 14.277273 | W31: 16.212564 | AF31: 2786.5216 | AG31: 3081.8254 | AH31: 3508.5059 | AQ31: 125.63636 | AR31: 138.48571 | AS31: 154.75 | BB31: 0.17860803 | BC31: 0.42081906 | BD31: 0.43128534 | BE31: 0.40207538 | BF31: 0.39876521 | BG31: 0.92495001 | BH31: 0.93331427 | BI31: 0.27069651 | BJ31: 0.27087855 | BK31: 0.82586786 | BL31: 0.0067708333 | BM31: 19 | BN31: 6.3 | BO31: 13.493866 | BP31: 14.886587 | BQ31: 16.905691 | BZ31: 8 | CA31: 10 | CB31: 12 | CC31: 15 | CD31: 19 | CE31: 20
B32: P030 | C32: Male | D32: 29 | E32: 1.753 | F32: 74.6 | G32: 5 | H32: 50 | I32: No | J32: 0.027662037 | K32: 14.478503 | L32: 43.872298 | M32: 1.11 | N32: 204 | O32: 20 | P32: 17 | Q32: 18 | R32: 23.788204 | S32: 38.716368 | T32: 728 | U32: 11.531538 | V32: 12.3548 | W32: 13.381923 | X32: 13.635312 | Y32: 14.154687 | AF32: 2334.0434 | AG32: 2454.8454 | AH32: 2679.5228 | AI32: 2711.4485 | AJ32: 2790.4127 | AQ32: 139.59259 | AR32: 151.92 | AS32: 161.7037 | AT32: 175.8125 | AU32: 183.38235 | BB32: 0.18637341 | BC32: 0.42767957 | BD32: 0.42998762 | BE32: 0.39916398 | BF32: 0.40248031 | BG32: 0.92624159 | BH32: 0.92991067 | BI32: 0.27428872 | BJ32: 0.27115064 | BK32: 0.82492387 | BM32: 20 | BN32: 4.6 | BO32: 11.745616 | BP32: 12.290883 | BQ32: 13.315373 | BR32: 13.624674 | BS32: 14.153097 | BZ32: 10 | CA32: 11 | CB32: 12 | CC32: 14 | CD32: 15 | CE32: 16 | CF32: 18 | CG32: 19 | CH32: 20
B33: P031 | C33: Male | D33: 40 | E33: 1.827 | F33: 69 | G33: 6 | H33: 75 | I33: No | J33: 0.026041667 | K33: 14.289507 | L33: 59.838554 | M33: 0.84 | N33: 175 | O33: 20 | P33: 17 | Q33: 17 | R33: 22.424158 | S33: 36.587116 | T33: 722.00146 | U33: 12.675185 | V33: 13.192333 | W33: 14.255313 | X33: 14.796857 | Y33: 15.691892 | AF33: 2614.9379 | AG33: 2726.2827 | AH33: 2952.6785 | AI33: 3060.1495 | AJ33: 3238.0027 | AQ33: 116.73333 | AR33: 129.25 | AS33: 140.17647 | AT33: 148.35135 | AU33: 155.97368 | BB33: 0.17999711 | BC33: 0.44308305 | BD33: 0.44561809 | BE33: 0.4124592 | BF33: 0.40853738 | BG33: 0.96021579 | BH33: 0.96224583 | BI33: 0.31285489 | BJ33: 0.30839896 | BK33: 0.86576919 | BL33: 0.019548611 | BM33: 19 | BN33: 7.8 | BO33: 12.929839 | BP33: 13.499067 | BQ33: 14.577968 | BR33: 15.117075 | BS33: 16.045566 | BZ33: 7 | CA33: 8 | CB33: 12 | CC33: 13 | CD33: 15 | CE33: 17 | CF33: 18 | CG33: 20
B34: P032 | C34: Male | D34: 27 | E34: 1.812 | F34: 72 | G34: 4 | H34: 25 | I34: No | J34: 0.032638889 | K34: 13.293228 | L34: 48.293394 | M34: 1.06 | N34: 198 | O34: 20 | P34: 15 | Q34: 16 | R34: 23.517597 | S34: 36.558483 | T34: 726 | U34: 12.6915 | V34: 13.727143 | W34: 14.025185 | X34: 15.1228 | AF34: 2556.2066 | AG34: 2755.0145 | AH34: 2811.2231 | AI34: 3021.9993 | AQ34: 148.85714 | AR34: 166.47826 | AS34: 170.96296 | AT34: 181 | BB34: 0.18206772 | BC34: 0.43670143 | BD34: 0.43273021 | BE34: 0.42249292 | BF34: 0.41990993 | BG34: 0.96713371 | BH34: 0.95943005 | BI34: 0.2863461 | BJ34: 0.28636185 | BK34: 0.84871812 | BL34: 0.012847222 | BM34: 20 | BN34: 8.7 | BO34: 12.823613 | BP34: 13.788158 | BQ34: 14.105903 | BR34: 15.165264 | BZ34: 10 | CA34: 12 | CB34: 13 | CC34: 15 | CD34: 16 | CE34: 18 | CF34: 20
B35: P033 | C35: Male | D35: 31 | E35: 1.749 | F35: 63.4 | G35: 8 | H35: 90 | I35: Shin ankle pain due to partially collapsed arch in April 2019 | J35: 0.021678241 | K35: 17.113966 | L35: 54.298318 | M35: 1.04 | N35: 190 | O35: 20 | P35: 20 | Q35: 21 | R35: 20.657376 | S35: 28.443486 | T35: 750.91239 | U35: 10.125185 | V35: 10.6336 | W35: 11.394 | X35: 12.459687 | Y35: 12.898125 | Z35: 13.916061 | AA35: 14.355833 | AB35: 15.08725 | AF35: 2056.601 | AG35: 2152.8099 | AH35: 2283.4432 | AI35: 2475.9697 | AJ35: 2583.6199 | AK35: 2798.2594 | AL35: 2869.2792 | AM35: 2985.5536 | AQ35: 111.55172 | AR35: 117.62963 | AS35: 126.06452 | AT35: 134.23529 | AU35: 145.67647 | AV35: 154.02857 | AW35: 161.82051 | AX35: 169.7619 | BB35: 0.16864703 | BC35: 0.42223395 | BD35: 0.43812945 | BE35: 0.41491927 | BF35: 0.41186783 | BG35: 0.93240798 | BH35: 0.94455057 | BI35: 0.28158265 | BJ35: 0.28643999 | BK35: 0.81052073 | BL35: 0.024837963 | BM35: 20 | BN35: 7.2 | BO35: 10.21365 | BP35: 10.828108 | BQ35: 11.478178 | BR35: 12.505353 | BS35: 13.040489 | BT35: 14.048012 | BU35: 14.377458 | BV35: 15.047409 | BZ35: 7 | CA35: 8 | CB35: 9 | CC35: 10 | CD35: 11 | CE35: 13 | CF35: 15 | CG35: 16 | CH35: 18 | CI35: 19 | CJ35: 20 | CK35: 20
B36: P034 | C36: Male | D36: 23 | E36: 1.819 | F36: 70 | G36: 3 | H36: 20 | I36: No | J36: 0.031944444 | K36: 13.903149 | L36: 42.711824 | M36: 1.61 | N36: 185 | O36: 19 | P36: 16 | Q36: 16 | R36: 23.781942 | S36: 40.061871 | T36: 751 | U36: 11.597778 | V36: 12.071373 | W36: 12.249273 | X36: 13.145172 | AF36: 2349.8259 | AG36: 2414.5716 | AH36: 2425.7234 | AI36: 2572.5075 | AQ36: 140.2449 | AR36: 154.07547 | AS36: 164.01724 | AT36: 170.35 | BB36: 0.16911066 | BC36: 0.47549443 | BD36: 0.47613511 | BE36: 0.4355981 | BF36: 0.43068782 | BG36: 1.0080543 | BH36: 1.0023366 | BI36: 0.27681681 | BJ36: 0.27601483 | BK36: 0.81380458 | BL36: 0.0075925926 | BM36: 19 | BN36: 10.3 | BO36: 11.737838 | BP36: 12.12756 | BQ36: 12.242116 | BR36: 13.065708 | BZ36: 9 | CA36: 12 | CB36: 13 | CC36: 14 | CD36: 15 | CE36: 18 | CF36: 19
B37: P035 | C37: Male | D37: 46 | E37: 1.785 | F37: 80.2 | G37: 4 | H37: 40 | I37: No | J37: 0.029166667 | K37: 14.113607 | L37: 46.064998 | M37: 1.16 | N37: 165 | O37: 18 | P37: 16 | Q37: 16 | R37: 22.409047 | S37: 35.737354 | T37: 734.00195 | U37: 12.186316 | V37: 13.5045 | W37: 14.434545 | X37: 15.919167 | Y37: 17.407037 | AF37: 2440.3187 | AG37: 2702.0013 | AH37: 2869.7297 | AI37: 3151.373 | AJ37: 3435.7957 | AQ37: 115.1 | AR37: 125.66667 | AS37: 133.16667 | AT37: 140.65385 | AU37: 148.7931 | BB37: 0.1929931 | BC37: 0.42679636 | BD37: 0.4249694 | BE37: 0.42014002 | BF37: 0.42164803 | BG37: 0.95074955 | BH37: 0.95084801 | BI37: 0.30533763 | BJ37: 0.3020367 | BK37: 0.83420122 | BL37: 0.010324074 | BM37: 19 | BN37: 7.2 | BO37: 12.27297 | BP37: 13.548693 | BQ37: 14.452442 | BR37: 15.904489 | BS37: 17.365211 | BZ37: 10 | CA37: 11 | CB37: 12 | CC37: 13 | CD37: 15 | CE37: 17 | CF37: 18 | CG37: 20
B38: P036 | C38: Male | D38: 18 | E38: 1.827 | F38: 75.6 | G38: 3 | H38: 10 | I38: No | J38: 0.032638889 | K38: 12.967262 | L38: 41.221505 | M38: 1.52 | N38: 204 | O38: 19 | P38: 15 | Q38: 15 | R38: 21.844506 | S38: 33.988933 | T38: 743 | U38: 12.84 | V38: 13.481026 | W38: 14.060238 | AF38: 2574.534 | AG38: 2690.4478 | AH38: 2784.3182 | AQ38: 154.94737 | AR38: 170.04762 | AS38: 180.62222 | BB38: 0.17173579 | BC38: 0.4598511 | BD38: 0.4622658 | BE38: 0.44475017 | BF38: 0.44654862 | BG38: 1.0062855 | BH38: 1.0098091 | BI38: 0.27851925 | BJ38: 0.27666953 | BK38: 0.81895273 | BL38: 0.012789352 | BM38: 20 | BN38: 7.9 | BO38: 12.910268 | BP38: 13.499253 | BQ38: 14.025059 | BZ38: 10 | CA38: 11 | CB38: 11 | CC38: 13 | CD38: 15 | CE38: 19
B39: P037 | C39: Male | D39: 32 | E39: 1.813 | F39: 67.7 | G39: 4 | H39: 45 | I39: No | J39: 0.025694444 | K39: 14.85902 | L39: 52.453901 | M39: 1.39 | N39: 174 | O39: 19 | P39: 17 | Q39: 18 | R39: 21.558504 | S39: 28.717323 | T39: 744.89213 | U39: 11.2392 | V39: 11.063846 | W39: 12.337368 | X39: 12.2288 | Y39: 13.276667 | AF39: 2260.8006 | AG39: 2212.7554 | AH39: 2459.7577 | AI39: 2421.6207 | AJ39: 2623.5358 | AQ39: 125.62963 | AR39: 129.07143 | AS39: 136.47368 | AT39: 143.55556 | AU39: 150.67857 | BB39: 0.18269206 | BC39: 0.434631 | BD39: 0.4407167 | BE39: 0.40495989 | BF39: 0.39872294 | BG39: 0.93044989 | BH39: 0.93479699 | BI39: 0.28811998 | BJ39: 0.29331308 | BK39: 0.88037656 | BL39: 0.016134259 | BM39: 19 | BN39: 3.9 | BO39: 11.207698 | BP39: 11.091672 | BQ39: 12.412376 | BR39: 12.181686 | BS39: 13.252187 | BZ39: 8 | CA39: 10 | CB39: 12 | CC39: 13 | CD39: 14 | CE39: 15 | CF39: 16 | CG39: 18 | CH39: 19
B40: P038 | C40: Female | D40: 26 | E40: 1.76 | F40: 71.6 | G40: 5 | H40: 30 | J40: 0.035416667 | K40: 12.569652 | L40: 39.839954 | M40: 1.2 | N40: 189 | O40: 20 | P40: 14 | Q40: 15 | R40: 22.328676 | S40: 45.532169 | T40: 748 | U40: 10.842143 | V40: 12.026667 | W40: 13.075625 | AF40: 2236.8869 | AG40: 2449.9209 | AH40: 2641.956 | AQ40: 142.13793 | AR40: 158.0625 | AS40: 172.4 | BB40: 0.15899419 | BC40: 0.44845066 | BD40: 0.45223362 | BE40: 0.40071843 | BF40: 0.40422501 | BG40: 0.95328065 | BH40: 0.95455221 | BI40: 0.2648309 | BJ40: 0.26537715 | BK40: 0.80608357 | BL40: 0.0099884259 | BM40: 20 | BN40: 8.9 | BO40: 11.039431 | BP40: 12.189883 | BQ40: 13.198536 | BZ40: 11 | CA40: 12 | CB40: 13 | CC40: 16 | CD40: 17 | CE40: 20
B41: P039 | C41: Male | D41: 42 | E41: 1.78 | F41: 79 | G41: 3 | H41: 35 | I41: No | J41: 0.028819444 | K41: 14.114516 | L41: 42.199161 | M41: 1.14 | N41: 187 | O41: 20 | P41: 16 | Q41: 17 | R41: 21.038221 | S41: 40.093815 | T41: 727.12092 | U41: 11.465217 | V41: 12.3816 | W41: 12.771935 | X41: 13.988788 | Y41: 16.075714 | AF41: 2314.693 | AG41: 2487.3306 | AH41: 2559.1779 | AI41: 2792.9152 | AJ41: 3194.908 | AQ41: 126.42308 | AR41: 137.25926 | AS41: 148.94118 | AT41: 160.69444 | AU41: 169.88889 | BB41: 0.18131328 | BC41: 0.42535328 | BD41: 0.42773091 | BE41: 0.40692051 | BF41: 0.40165881 | BG41: 0.93735281 | BH41: 0.93969169 | BI41: 0.27638024 | BJ41: 0.2783476 | BK41: 0.84147775 | BL41: 0.014907407 | BM41: 20 | BN41: 9.2 | BO41: 11.56799 | BP41: 12.457192 | BQ41: 12.837213 | BR41: 14.044681 | BS41: 16.096478 | BZ41: 10 | CA41: 11 | CB41: 13 | CC41: 14 | CD41: 15 | CE41: 17 | CF41: 19 | CG41: 20
...

Sheet Results
B2: Participants | D2: Age | F2: Height | H2: Mass | J2: RunningDaysAWeek | L2: KmAWeek | N2: Time10K | P2: LT | R2: VO2max | T2: Temperature | V2: Humidity | X2: Pressure | Z2: Completed speeds | AP2: Submax speeds | BA2: Temperature | BC2: Humidty
C3: n | D3: mean | E3: sd | F3: mean | G3: sd | H3: mean | I3: sd | J3: mean | K3: sd | L3: mean | M3: sd | N3: mean | O3: sd | P3: mean | Q3: sd | R3: mean | S3: sd | T3: mean | U3: sd | V3: mean | W3: sd | X3: mean | Y3: sd | Z3: 10 | AA3: 11 | AB3: 12 | AC3: 13 | AD3: 14 | AE3: 15 | AF3: 16 | AG3: 17 | AH3: 18 | AI3: 19 | AJ3: 20 | AK3: 21 | AL3: 22 | AM3: 23 | AN3: 24 | AO3: 25 | AP3: 10 | AQ3: 11 | AR3: 12 | AS3: 13 | AT3: 14 | AU3: 15 | AV3: 16 | AW3: 17 | AX3: 18 | AY3: 19 | AZ3: 20 | BA3: mean | BB3: sd | BC3: mean | BD3: sd
B4: Female | C4: =COUNTIF(Sheet1!C:C, "Female") -> 50 | D4: =AVERAGEIF(Sheet1!C:C,"Female",Sheet1!D:D) -> 33.96 | E4: {=STDEV(IF(Sheet1!$C:$C="Female",Sheet1!$D:$D,""))} -> 9.7435693 | F4: =AVERAGEIF(Sheet1!C:C,"Female",Sheet1!E:E) -> 1.6582 | G4: {=STDEV(IF(Sheet1!$C:$C="Female",Sheet1!$E:$E,""))} -> 0.060487813 | H4: =AVERAGEIF(Sheet1!C:C,"Female",Sheet1!F:F) -> 58.438 | I4: {=STDEV(IF(Sheet1!$C:$C="Female",Sheet1!$F:$F,""))} -> 6.1720532 | J4: =AVERAGEIF(Sheet1!C:C,"Female",Sheet1!G:G) -> 4.5 | K4: {=STDEV(IF(Sheet1!$C:$C="Female",Sheet1!$G:$G,""))} -> 1.4033488 | L4: =AVERAGEIF(Sheet1!C:C,"Female",Sheet1!H:H) -> 48.592 | M4: {=STDEV(IF(Sheet1!$C:$C="Female",Sheet1!$H:$H,""))} -> 25.557952 | N4: =AVERAGEIF(Sheet1!C:C,"Female",Sheet1!J:J) -> 0.031660648 | O4: {=STDEV(IF(Sheet1!$C:$C="Female",Sheet1!$J:$J,""))} -> 0.0043475372 | P4: =AVERAGEIF(Sheet1!C:C,"Female",Sheet1!K:K) -> 13.103589 | Q4: {=STDEV(IF(Sheet1!$C:$C="Female",Sheet1!$K:$K,""))} -> 1.1488888 | R4: =AVERAGEIF(Sheet1!C:C,"Female",Sheet1!L:L) -> 48.563634 | S4: {=STDEV(IF(Sheet1!$C:$C="Female",Sheet1!$L:$L,""))} -> 6.0927179 | Z4: =COUNTIFS(Sheet1!C3:C114, "=Male", Sheet1!P3:P114, ">=10") -> 50 | AA4: =COUNTIFS(Sheet1!C3:C114, "=Male", Sheet1!P3:P114, ">=11") -> 50 | AB4: =COUNTIFS(Sheet1!C3:C114, "=Male", Sheet1!P3:P114, ">=12") -> 50 | AC4: =COUNTIFS(Sheet1!C3:C114, "=Male", Sheet1!P3:P114, ">=13") -> 50 | AD4: =COUNTIFS(Sheet1!C3:C114, "=Male", Sheet1!P3:P114, ">=14") -> 50 | AE4: =COUNTIFS(Sheet1!C3:C114, "=Male", Sheet1!P3:P114, ">=15") -> 48 | AF4: =COUNTIFS(Sheet1!C3:C114, "=Male", Sheet1!P3:P114, ">=16") -> 41 | AG4: =COUNTIFS(Sheet1!C3:C114, "=Male", Sheet1!P3:P114, ">=17") -> 30 | AH4: =COUNTIFS(Sheet1!C3:C114, "=Male", Sheet1!P3:P114, ">=18") -> 11 | AI4: =COUNTIFS(Sheet1!C3:C114, "=Male", Sheet1!P3:P114, ">=19") -> 2 | AJ4: =COUNTIFS(Sheet1!C3:C114, "=Male", Sheet1!P3:P114, ">=20") -> 1 | AK4: =COUNTIFS(Sheet1!C3:C114, "=Male", Sheet1!P3:P114, ">=21") -> 0 | AL4: =COUNTIFS(Sheet1!C3:C114, "=Male", Sheet1!P3:P114, ">=22") -> 0 | AM4: =COUNTIFS(Sheet1!C3:C114, "=Male", Sheet1!P3:P114, ">=23") -> 0 | AN4: =COUNTIFS(Sheet1!C3:C114, "=Male", Sheet1!P3:P114, ">=24") -> 0 | AO4: =COUNTIFS(Sheet1!C3:C114, "=Male", Sheet1!P3:P114, ">=25") -> 0 | AP4: =COUNTIFS(Sheet1!$C$3:$C$114, "=Male", Sheet1!U3:U114, "<>") -> 50 | AQ4: =COUNTIFS(Sheet1!$C$3:$C$114, "=Male", Sheet1!V3:V114, "<>") -> 50 | AR4: =COUNTIFS(Sheet1!$C$3:$C$114, "=Male", Sheet1!W3:W114, "<>") -> 49 | AS4: =COUNTIFS(Sheet1!$C$3:$C$114, "=Male", Sheet1!X3:X114, "<>") -> 45 | AT4: =COUNTIFS(Sheet1!$C$3:$C$114, "=Male", Sheet1!Y3:Y114, "<>") -> 36 | AU4: =COUNTIFS(Sheet1!$C$3:$C$114, "=Male", Sheet1!Z3:Z114, "<>") -> 13 | AV4: =COUNTIFS(Sheet1!$C$3:$C$114, "=Male", Sheet1!AA3:AA114, "<>") -> 2 | AW4: =COUNTIFS(Sheet1!$C$3:$C$114, "=Male", Sheet1!AB3:AB114, "<>") -> 1 | ... AZ4: =COUNTIFS(Sheet1!$C$3:$C$114, "=Male", Sheet1!AE3:AE114, "<>") -> 0
B5: Male | C5: =COUNTIF(Sheet1!C:C, "Male") -> 50 | D5: =AVERAGEIF(Sheet1!C:C,"Male",Sheet1!D:D) -> 34.88 | E5: {=STDEV(IF(Sheet1!$C:$C="Male",Sheet1!$D:$D,""))} -> 9.7512741 | F5: =AVERAGEIF(Sheet1!C:C,"Male",Sheet1!E:E) -> 1.7908 | G5: {=STDEV(IF(Sheet1!$C:$C="Male",Sheet1!$E:$E,""))} -> 0.056513318 | H5: =AVERAGEIF(Sheet1!C:C,"Male",Sheet1!F:F) -> 73.01 | I5: =STDEV(IF(Sheet1!$C:$C="Male",Sheet1!$F:$F,"")) -> 9.8410819 | J5: =AVERAGEIF(Sheet1!C:C,"Male",Sheet1!G:G) -> 4.08 | K5: {=STDEV(IF(Sheet1!$C:$C="Male",Sheet1!$G:$G,""))} -> 1.4685825 | L5: =AVERAGEIF(Sheet1!C:C,"Male",Sheet1!H:H) -> 42.484 | M5: {=STDEV(IF(Sheet1!$C:$C="Male",Sheet1!$H:$H,""))} -> 24.699801 | N5: =AVERAGEIF(Sheet1!C:C,"Male",Sheet1!J:J) -> 0.02772963 | O5: {=STDEV(IF(Sheet1!$C:$C="Male",Sheet1!$J:$J,""))} -> 0.0027598365 | P5: =AVERAGEIF(Sheet1!C:C,"Male",Sheet1!K:K) -> 14.39814 | Q5: {=STDEV(IF(Sheet1!$C:$C="Male",Sheet1!$K:$K,""))} -> 0.96241901 | R5: =AVERAGEIF(Sheet1!C:C,"Male",Sheet1!L:L) -> 52.326808 | S5: {=STDEV(IF(Sheet1!$C:$C="Male",Sheet1!$L:$L,""))} -> 7.005961 | Z5: =COUNTIFS(Sheet1!C3:C114, "=Female", Sheet1!P3:P114, ">=10") -> 50 | AA5: =COUNTIFS(Sheet1!C3:C114, "=Female", Sheet1!P3:P114, ">=11") -> 50 | AB5: =COUNTIFS(Sheet1!C3:C114, "=Female", Sheet1!P3:P114, ">=12") -> 50 | AC5: =COUNTIFS(Sheet1!C3:C114, "=Female", Sheet1!P3:P114, ">=13") -> 47 | AD5: =COUNTIFS(Sheet1!C3:C114, "=Female", Sheet1!P3:P114, ">=14") -> 37 | AE5: =COUNTIFS(Sheet1!C3:C114, "=Female", Sheet1!P3:P114, ">=15") -> 27 | AF5: =COUNTIFS(Sheet1!C3:C114, "=Female", Sheet1!P3:P114, ">=16") -> 17 | AG5: =COUNTIFS(Sheet1!C3:C114, "=Female", Sheet1!P3:P114, ">=17") -> 9 | AH5: =COUNTIFS(Sheet1!C3:C114, "=Female", Sheet1!P3:P114, ">=18") -> 1 | AI5: =COUNTIFS(Sheet1!C3:C114, "=Female", Sheet1!P3:P114, ">=19") -> 0 | AJ5: =COUNTIFS(Sheet1!C3:C114, "=Female", Sheet1!P3:P114, ">=20") -> 0 | AK5: =COUNTIFS(Sheet1!C3:C114, "=Female", Sheet1!P3:P114, ">=21") -> 0 | AL5: =COUNTIFS(Sheet1!C3:C114, "=Female", Sheet1!P3:P114, ">=22") -> 0 | AM5: =COUNTIFS(Sheet1!C3:C114, "=Female", Sheet1!P3:P114, ">=23") -> 0 | AN5: =COUNTIFS(Sheet1!C3:C114, "=Female", Sheet1!P3:P114, ">=24") -> 0 | AO5: =COUNTIFS(Sheet1!C3:C114, "=Female", Sheet1!P3:P114, ">=25") -> 0 | AP5: =COUNTIFS(Sheet1!$C$3:$C$114, "=Female", Sheet1!U3:U114, "<>") -> 47 | AQ5: =COUNTIFS(Sheet1!$C$3:$C$114, "=Female", Sheet1!V3:V114, "<>") -> 50 | AR5: =COUNTIFS(Sheet1!$C$3:$C$114, "=Female", Sheet1!W3:W114, "<>") -> 36 | AS5: =COUNTIFS(Sheet1!$C$3:$C$114, "=Female", Sheet1!X3:X114, "<>") -> 27 | AT5: =COUNTIFS(Sheet1!$C$3:$C$114, "=Female", Sheet1!Y3:Y114, "<>") -> 12 | AU5: =COUNTIFS(Sheet1!$C$3:$C$114, "=Female", Sheet1!Z3:Z114, "<>") -> 2 | AV5: =COUNTIFS(Sheet1!$C$3:$C$114, "=Female", Sheet1!AA3:AA114, "<>") -> 0 | AW5: =COUNTIFS(Sheet1!$C$3:$C$114, "=Female", Sheet1!AB3:AB114, "<>") -> 0 | ... AZ5: =COUNTIFS(Sheet1!$C$3:$C$114, "=Female", Sheet1!AE3:AE114, "<>") -> 0
B6: All | C6: =C4+C5 -> 100 | D6: =AVERAGE(Sheet1!D:D) -> 34.42 | E6: =STDEV(Sheet1!D:D) -> 9.7090815 | F6: =AVERAGE(Sheet1!E:E) -> 1.7245 | G6: =STDEV(Sheet1!E:E) -> 0.088497161 | H6: =AVERAGE(Sheet1!F:F) -> 65.724 | I6: =STDEV(Sheet1!F:F) -> 9.8410819 | J6: =AVERAGE(Sheet1!G:G) -> 4.29 | K6: =STDEV(Sheet1!G:G) -> 1.4445649 | L6: =AVERAGE(Sheet1!H:H) -> 45.538 | M6: =STDEV(Sheet1!H:H) -> 25.192964 | N6: =AVERAGE(Sheet1!J:J) -> 0.029695139 | O6: =STDEV(Sheet1!J:J) -> 0.004126404 | P6: =AVERAGE(Sheet1!K:K) -> 13.750865 | Q6: =STDEV(Sheet1!K:K) -> 1.2389313 | R6: =AVERAGE(Sheet1!L:L) -> 50.445221 | S6: =STDEV(Sheet1!L:L) -> 6.8002283 | T6: =AVERAGE(Sheet1!R:R) -> 22.042205 | U6: =STDEV(Sheet1!R:R) -> 1.2042161 | V6: =AVERAGE(Sheet1!S:S) -> 37.977204 | W6: =STDEV(Sheet1!S:S) -> 7.8555998 | X6: =AVERAGE(Sheet1!T:T) -> 745.3956 | Y6: =STDEV(Sheet1!T:T) -> 10.787945 | Z6: =COUNTIF(Sheet1!P3:P114, ">=10") -> 100 | AA6: =COUNTIF(Sheet1!P3:P114, ">=11") -> 100 | AB6: =COUNTIF(Sheet1!P3:P114, ">=12") -> 100 | AC6: =COUNTIF(Sheet1!P3:P114, ">=13") -> 97 | AD6: =COUNTIF(Sheet1!P3:P114, ">=14") -> 87 | AE6: =COUNTIF(Sheet1!P3:P114, ">=15") -> 75 | AF6: =COUNTIF(Sheet1!P3:P114, ">=16") -> 58 | AG6: =COUNTIF(Sheet1!P3:P114, ">=17") -> 39 | AH6: =COUNTIF(Sheet1!P3:P114, ">=18") -> 12 | AI6: =COUNTIF(Sheet1!P3:P114, ">=19") -> 2 | AJ6: =COUNTIF(Sheet1!P3:P114, ">=20") -> 1 | AK6: =COUNTIF(Sheet1!P3:P114, ">=21") -> 0 | AL6: =COUNTIF(Sheet1!P3:P114, ">=22") -> 0 | AM6: =COUNTIF(Sheet1!P3:P114, ">=23") -> 0 | AN6: =COUNTIF(Sheet1!P3:P114, ">=24") -> 0 | AO6: =COUNTIF(Sheet1!P3:P114, ">=25") -> 0 | AP6: =COUNTIF(Sheet1!U3:U114, "<>") -> 97 | AQ6: =COUNTIF(Sheet1!V3:V114, "<>") -> 100 | AR6: =COUNTIF(Sheet1!W3:W114, "<>") -> 85 | AS6: =COUNTIF(Sheet1!X3:X114, "<>") -> 72 | AT6: =COUNTIF(Sheet1!Y3:Y114, "<>") -> 48 | AU6: =COUNTIF(Sheet1!Z3:Z114, "<>") -> 15 | AV6: =COUNTIF(Sheet1!AA3:AA114, "<>") -> 2 | AW6: =COUNTIF(Sheet1!AB3:AB114, "<>") -> 1 | ... AZ6: =COUNTIF(Sheet1!AE3:AE114, "<>") -> 0 | BA6: =AVERAGE(Sheet1!R:R) -> 22.042205 | BB6: =_xlfn.STDEV.P(Sheet1!R:R) -> 1.1981798 | BC6: =AVERAGE(Sheet1!S:S) -> 37.977204 | BD6: =_xlfn.STDEV.P(Sheet1!S:S) -> 7.8162231
